const x = 10

try {

    console

} catch(err) {
    console.log(`Erro: ${err}`)
}